//! MANEJO DE ERRORES


'use strict'

try {
    let x = 10;
    //myFuction()
}
catch(err){
    console.log(err.message)
}
finally{
    console.log('Ejecute..')
}

console.log('examplee continuee ....')